Workbook

Sheet README
A1: Project Name: Call Center Performance Dashboard
A2: Tool Used: Microsoft Excel
A3: Skills: Pivot Tables, Pivot Charts, Slicers, KPI Analysis, Dashboard Design, Data Visualization
A6: CALL CENTER PERFORMANCE DASHBOARD
A8: Project Overview
A10: This Excel dashboard analyzes call center performance using key operational metrics such as incoming calls, answered calls, answer rate, abandoned calls, waiting time, and service level.
A11: The dashboard helps monitor customer service performance and identify trends that may impact customer experience.
A15: Objective
A17: The purpose of this project is to:
A19: Monitor call center activity
A20: Track answering performance
A21: Measure service efficiency
... A29: The dataset contains call center performance records with the following fields:
A31: Column | B31: Description
A32: Incoming Calls | B32: Total calls received
A33: Answered Calls | B33: Total calls answered
A34: Answer Rate | B34: Percentage of calls answered
A35: Abandoned Calls | B35: Calls abandoned before being answered
A36: Answer Speed (AVG) | B36: Average time to answer a call
A37: Talk Duration (AVG) | B37: Average call duration
A38: Waiting Time (AVG) | B38: Average customer waiting time
A39: Service Level (20 Seconds) | B39: Percentage of calls answered within 20 seconds
A42: Data Preparation
A44: The following steps were performed before creating the dashboard:
A46: Checked for missing values
A47: Verified data types
A48: Formatted percentage fields
A49: Formatted time-related columns
A50: Converted the dataset into an Excel Table
A53: Key Performance Indicators (KPIs)
A55: Total Incoming Calls
A56: Total number of calls received.
A58: Total Answered Calls
A59: Total number of calls successfully answered.
... A133: Workbook Structure
A135: Worksheet | B135: Purpose
A136: README | B136: Project documentation
A137: Raw_Data | B137: Original dataset
A138: Working_Sheet | B138: Data preparation and calculations
A139: Pivot_Tables | B139: Pivot tables used for charts
...

Sheet Call Center Data
A1: Index | B1: Incoming Calls | C1: Answered Calls | D1: Answer Rate | E1: Abandoned Calls | F1: Answer Speed (AVG) | G1: Talk Duration (AVG) | H1: Waiting Time (AVG) | I1: Service Level (20 Seconds)
A2: 1 | B2: 217 | C2: 204 | D2: 0.9401 | E2: 13 | F2: 0.00019675926 | G2: 0.0015509259 | H2: 0.0019097222 | I2: 0.7628
A3: 2 | B3: 200 | C3: 182 | D3: 0.91 | E3: 18 | F3: 0.00023148148 | G3: 0.0016435185 | H3: 0.0048032407 | I3: 0.7273
A4: 3 | B4: 216 | C4: 198 | D4: 0.9167 | E4: 18 | F4: 0.00020833333 | G4: 0.0018287037 | H4: 0.002662037 | I4: 0.743
A5: 4 | B5: 155 | C5: 145 | D5: 0.9355 | E5: 10 | F5: 0.00017361111 | G5: 0.001724537 | H5: 0.0022222222 | I5: 0.7961
A6: 5 | B6: 37 | C6: 37 | D6: 1 | E6: 0 | F6: 3.4722222e-05 | G6: 0.0014583333 | H6: 0.00040509259 | I6: 0.973
A7: 6 | B7: 315 | C7: 304 | D7: 0.9651 | E7: 11 | F7: 0.00020833333 | G7: 0.001099537 | H7: 0.0018171296 | I7: 0.7717
A8: 7 | B8: 252 | C8: 244 | D8: 0.9683 | E8: 8 | F8: 0.00015046296 | G8: 0.0012731481 | H8: 0.001412037 | I8: 0.82
A9: 8 | B9: 213 | C9: 205 | D9: 0.9624 | E9: 8 | F9: 0.00011574074 | G9: 0.0015046296 | H9: 0.002337963 | I9: 0.881
A10: 9 | B10: 219 | C10: 200 | D10: 0.9132 | E10: 19 | F10: 0.00017361111 | G10: 0.0015972222 | H10: 0.0043055556 | I10: 0.7945
A11: 10 | B11: 371 | C11: 348 | D11: 0.938 | E11: 23 | F11: 0.00021990741 | G11: 0.0011574074 | H11: 0.0024189815 | I11: 0.7363
A12: 11 | B12: 166 | C12: 164 | D12: 0.988 | E12: 2 | F12: 0.00013888889 | G12: 0.0015046296 | H12: 0.0019212963 | I12: 0.8133
A13: 12 | B13: 32 | C13: 32 | D13: 1 | E13: 0 | F13: 2.3148148e-05 | G13: 0.0014236111 | H13: 3.4722222e-05 | I13: 1
... A1252: 1251 | B1252: 12 | C1252: 11 | D1252: 0.9167 | E1252: 1 | F1252: 3.4722222e-05 | G1252: 0.0015277778 | H1252: 0.0006712963 | I1252: 0.9167

Sheet Worksheet
A1: Incoming Calls | B1: Answered Calls | C1: Answer Rate | D1: Abandoned Calls | E1: Answer Speed (AVG) | F1: Talk Duration (AVG) | G1: Waiting Time (AVG) | H1: Service Level (20 Seconds) | I1: Answer Rate Numeric | J1: Service Level Numeric | K1: Calls Not Answered | L1: Abandonment Rate | M1: Answer Efficiency | O1: KPI SUMMARY
A2: 217 | B2: 204 | C2: 0.9401 | D2: 13 | E2: 0.00019675926 | F2: 0.0015509259 | G2: 0.0019097222 | H2: 0.76280093 | I2: =VALUE(SUBSTITUTE(C2,"%",""))/100 -> 0.009401 | J2: =VALUE(SUBSTITUTE(H2,"%",""))/100 -> 0.0076280093 | K2: =A2-B2 -> 13 | L2: =D2/A2 -> 0.059907834 | M2: =B2/A2 -> 0.94009217 | O2: Total Incoming Calls | P2: =SUM(A:A) -> 248373
A3: 200 | B3: 182 | C3: 0.91 | D3: 18 | E3: 0.00023148148 | F3: 0.0016435185 | G3: 0.0048032407 | H3: 0.7273 | I3: =VALUE(SUBSTITUTE(C3,"%",""))/100 -> 0.0091 | J3: =VALUE(SUBSTITUTE(H3,"%",""))/100 -> 0.007273 | K3: =A3-B3 -> 18 | L3: =D3/A3 -> 0.09 | M3: =B3/A3 -> 0.91 | O3: Total Answered Calls | P3: =SUM(B:B) -> 221234
A4: 216 | B4: 198 | C4: 0.9167 | D4: 18 | E4: 0.00020833333 | F4: 0.0018287037 | G4: 0.002662037 | H4: 0.743 | I4: =VALUE(SUBSTITUTE(C4,"%",""))/100 -> 0.009167 | J4: =VALUE(SUBSTITUTE(H4,"%",""))/100 -> 0.00743 | K4: =A4-B4 -> 18 | L4: =D4/A4 -> 0.083333333 | M4: =B4/A4 -> 0.91666667 | O4: Total Abandoned Calls | P4: =SUM(D:D) -> 27139
A5: 155 | B5: 145 | C5: 0.9355 | D5: 10 | E5: 0.00017361111 | F5: 0.001724537 | G5: 0.0022222222 | H5: 0.7961 | I5: =VALUE(SUBSTITUTE(C5,"%",""))/100 -> 0.009355 | J5: =VALUE(SUBSTITUTE(H5,"%",""))/100 -> 0.007961 | K5: =A5-B5 -> 10 | L5: =D5/A5 -> 0.064516129 | M5: =B5/A5 -> 0.93548387 | O5: Avg Answer Rate | P5: =AVERAGE(C:C) -> 0.92692518
A6: 37 | B6: 37 | C6: 1 | D6: 0 | E6: 3.4722222e-05 | F6: 0.0014583333 | G6: 0.00040509259 | H6: 0.973 | I6: =VALUE(SUBSTITUTE(C6,"%",""))/100 -> 0.01 | J6: =VALUE(SUBSTITUTE(H6,"%",""))/100 -> 0.00973 | K6: =A6-B6 -> 0 | L6: =D6/A6 -> 0 | M6: =B6/A6 -> 1 | O6: Avg Waiting Time | P6: =AVERAGE(G:G) -> 0.0026888304
A7: 315 | B7: 304 | C7: 0.9651 | D7: 11 | E7: 0.00020833333 | F7: 0.001099537 | G7: 0.0018171296 | H7: 0.7717 | I7: =VALUE(SUBSTITUTE(C7,"%",""))/100 -> 0.009651 | J7: =VALUE(SUBSTITUTE(H7,"%",""))/100 -> 0.007717 | K7: =A7-B7 -> 11 | L7: =D7/A7 -> 0.034920635 | M7: =B7/A7 -> 0.96507937 | O7: Avg Service Level | P7: =AVERAGE(H:H) -> 0.7087291
A8: 252 | B8: 244 | C8: 0.9683 | D8: 8 | E8: 0.00015046296 | F8: 0.0012731481 | G8: 0.001412037 | H8: 0.82 | I8: =VALUE(SUBSTITUTE(C8,"%",""))/100 -> 0.009683 | J8: =VALUE(SUBSTITUTE(H8,"%",""))/100 -> 0.0082 | K8: =A8-B8 -> 8 | L8: =D8/A8 -> 0.031746032 | M8: =B8/A8 -> 0.96825397
A9: 213 | B9: 205 | C9: 0.9624 | D9: 8 | E9: 0.00011574074 | F9: 0.0015046296 | G9: 0.002337963 | H9: 0.881 | I9: =VALUE(SUBSTITUTE(C9,"%",""))/100 -> 0.009624 | J9: =VALUE(SUBSTITUTE(H9,"%",""))/100 -> 0.00881 | K9: =A9-B9 -> 8 | L9: =D9/A9 -> 0.037558685 | M9: =B9/A9 -> 0.96244131 | O9: KPI SUMMARY
A10: 219 | B10: 200 | C10: 0.9132 | D10: 19 | E10: 0.00017361111 | F10: 0.0015972222 | G10: 0.0043055556 | H10: 0.7945 | I10: =VALUE(SUBSTITUTE(C10,"%",""))/100 -> 0.009132 | J10: =VALUE(SUBSTITUTE(H10,"%",""))/100 -> 0.007945 | K10: =A10-B10 -> 19 | L10: =D10/A10 -> 0.086757991 | M10: =B10/A10 -> 0.91324201 | O10: Answer Rate Numeric | P10: =AVERAGE(I:I) -> 0.0092692518
A11: 371 | B11: 348 | C11: 0.938 | D11: 23 | E11: 0.00021990741 | F11: 0.0011574074 | G11: 0.0024189815 | H11: 0.7363 | I11: =VALUE(SUBSTITUTE(C11,"%",""))/100 -> 0.00938 | J11: =VALUE(SUBSTITUTE(H11,"%",""))/100 -> 0.007363 | K11: =A11-B11 -> 23 | L11: =D11/A11 -> 0.061994609 | M11: =B11/A11 -> 0.93800539 | O11: Service Level Numeric | P11: =AVERAGE(J:J) -> 0.007087291
A12: 166 | B12: 164 | C12: 0.988 | D12: 2 | E12: 0.00013888889 | F12: 0.0015046296 | G12: 0.0019212963 | H12: 0.8133 | I12: =VALUE(SUBSTITUTE(C12,"%",""))/100 -> 0.00988 | J12: =VALUE(SUBSTITUTE(H12,"%",""))/100 -> 0.008133 | K12: =A12-B12 -> 2 | L12: =D12/A12 -> 0.012048193 | M12: =B12/A12 -> 0.98795181 | O12: Calls Not Answered | P12: =SUM(K:K) -> 27139
A13: 32 | B13: 32 | C13: 1 | D13: 0 | E13: 2.3148148e-05 | F13: 0.0014236111 | G13: 3.4722222e-05 | H13: 1 | I13: =VALUE(SUBSTITUTE(C13,"%",""))/100 -> 0.01 | J13: =VALUE(SUBSTITUTE(H13,"%",""))/100 -> 0.01 | K13: =A13-B13 -> 0 | L13: =D13/A13 -> 0 | M13: =B13/A13 -> 1 | O13: Abandonment Rate | P13: =AVERAGE(L:L) -> 0.073076569
A14: 231 | B14: 222 | C14: 0.961 | D14: 9 | E14: 9.2592593e-05 | F14: 0.0012615741 | G14: 0.0015972222 | H14: 0.8646 | I14: =VALUE(SUBSTITUTE(C14,"%",""))/100 -> 0.00961 | J14: =VALUE(SUBSTITUTE(H14,"%",""))/100 -> 0.008646 | K14: =A14-B14 -> 9 | L14: =D14/A14 -> 0.038961039 | M14: =B14/A14 -> 0.96103896 | O14: Answer Efficiency | P14: =AVERAGE(M:M) -> 0.92692343
A15: 205 | B15: 197 | C15: 0.961 | D15: 8 | E15: 8.1018519e-05 | F15: 0.0012962963 | G15: 0.0019444444 | H15: 0.9261 | I15: =VALUE(SUBSTITUTE(C15,"%",""))/100 -> 0.00961 | J15: =VALUE(SUBSTITUTE(H15,"%",""))/100 -> 0.009261 | K15: =A15-B15 -> 8 | L15: =D15/A15 -> 0.03902439 | M15: =B15/A15 -> 0.96097561
A16: 338 | B16: 313 | C16: 0.926 | D16: 25 | E16: 0.00015046296 | F16: 0.0012847222 | G16: 0.0025462963 | H16: 0.8006 | I16: =VALUE(SUBSTITUTE(C16,"%",""))/100 -> 0.00926 | J16: =VALUE(SUBSTITUTE(H16,"%",""))/100 -> 0.008006 | K16: =A16-B16 -> 25 | L16: =D16/A16 -> 0.073964497 | M16: =B16/A16 -> 0.9260355 | O16: KPI SUMMARY
A17: 180 | B17: 174 | C17: 0.9667 | D17: 6 | E17: 0.00015046296 | F17: 0.0015972222 | G17: 0.0023842593 | H17: 0.838 | I17: =VALUE(SUBSTITUTE(C17,"%",""))/100 -> 0.009667 | J17: =VALUE(SUBSTITUTE(H17,"%",""))/100 -> 0.00838 | K17: =A17-B17 -> 6 | L17: =D17/A17 -> 0.033333333 | M17: =B17/A17 -> 0.96666667 | O17: Answer Speed | P17: =AVERAGE(E:E) -> 0.00028816761
A18: 226 | B18: 211 | C18: 0.9336 | D18: 15 | E18: 0.00023148148 | F18: 0.0014351852 | G18: 0.0033912037 | H18: 0.7623 | I18: =VALUE(SUBSTITUTE(C18,"%",""))/100 -> 0.009336 | J18: =VALUE(SUBSTITUTE(H18,"%",""))/100 -> 0.007623 | K18: =A18-B18 -> 15 | L18: =D18/A18 -> 0.066371681 | M18: =B18/A18 -> 0.93362832 | O18: Talk Duration | P18: =AVERAGE(F:F) -> 0.0018235134
A19: 226 | B19: 212 | C19: 0.9381 | D19: 14 | E19: 0.00011574074 | F19: 0.0014236111 | G19: 0.0019097222 | H19: 0.8444 | I19: =VALUE(SUBSTITUTE(C19,"%",""))/100 -> 0.009381 | J19: =VALUE(SUBSTITUTE(H19,"%",""))/100 -> 0.008444 | K19: =A19-B19 -> 14 | L19: =D19/A19 -> 0.061946903 | M19: =B19/A19 -> 0.9380531 | O19: Waiting Time | P19: =AVERAGE(G:G) -> 0.0026888304
A20: 45 | B20: 44 | C20: 0.9778 | D20: 1 | E20: 2.3148148e-05 | F20: 0.0014351852 | G20: 0.00063657407 | H20: 0.9778 | I20: =VALUE(SUBSTITUTE(C20,"%",""))/100 -> 0.009778 | J20: =VALUE(SUBSTITUTE(H20,"%",""))/100 -> 0.009778 | K20: =A20-B20 -> 1 | L20: =D20/A20 -> 0.022222222 | M20: =B20/A20 -> 0.97777778
A21: 218 | B21: 194 | C21: 0.8899 | D21: 24 | E21: 0.00030092593 | F21: 0.0018865741 | G21: 0.0044907407 | H21: 0.6898 | I21: =VALUE(SUBSTITUTE(C21,"%",""))/100 -> 0.008899 | J21: =VALUE(SUBSTITUTE(H21,"%",""))/100 -> 0.006898 | K21: =A21-B21 -> 24 | L21: =D21/A21 -> 0.11009174 | M21: =B21/A21 -> 0.88990826
A22: 187 | B22: 174 | C22: 0.9305 | D22: 13 | E22: 0.00017361111 | F22: 0.0015740741 | G22: 0.0032291667 | H22: 0.8152 | I22: =VALUE(SUBSTITUTE(C22,"%",""))/100 -> 0.009305 | J22: =VALUE(SUBSTITUTE(H22,"%",""))/100 -> 0.008152 | K22: =A22-B22 -> 13 | L22: =D22/A22 -> 0.069518717 | M22: =B22/A22 -> 0.93048128
A23: 191 | B23: 184 | C23: 0.9634 | D23: 7 | E23: 0.00011574074 | F23: 0.0014930556 | G23: 0.0025462963 | H23: 0.8564 | I23: =VALUE(SUBSTITUTE(C23,"%",""))/100 -> 0.009634 | J23: =VALUE(SUBSTITUTE(H23,"%",""))/100 -> 0.008564 | K23: =A23-B23 -> 7 | L23: =D23/A23 -> 0.036649215 | M23: =B23/A23 -> 0.96335079
A24: 188 | B24: 174 | C24: 0.9255 | D24: 14 | E24: 0.00017361111 | F24: 0.0016782407 | G24: 0.0021875 | H24: 0.7688 | I24: =VALUE(SUBSTITUTE(C24,"%",""))/100 -> 0.009255 | J24: =VALUE(SUBSTITUTE(H24,"%",""))/100 -> 0.007688 | K24: =A24-B24 -> 14 | L24: =D24/A24 -> 0.074468085 | M24: =B24/A24 -> 0.92553191
A25: 154 | B25: 148 | C25: 0.961 | D25: 6 | E25: 0.00011574074 | F25: 0.0017013889 | G25: 0.0025 | H25: 0.8506 | I25: =VALUE(SUBSTITUTE(C25,"%",""))/100 -> 0.00961 | J25: =VALUE(SUBSTITUTE(H25,"%",""))/100 -> 0.008506 | K25: =A25-B25 -> 6 | L25: =D25/A25 -> 0.038961039 | M25: =B25/A25 -> 0.96103896
A26: 166 | B26: 150 | C26: 0.9036 | D26: 16 | E26: 0.00020833333 | F26: 0.0016898148 | G26: 0.0032175926 | H26: 0.7683 | I26: =VALUE(SUBSTITUTE(C26,"%",""))/100 -> 0.009036 | J26: =VALUE(SUBSTITUTE(H26,"%",""))/100 -> 0.007683 | K26: =A26-B26 -> 16 | L26: =D26/A26 -> 0.096385542 | M26: =B26/A26 -> 0.90361446
A27: 58 | B27: 57 | C27: 0.9828 | D27: 1 | E27: 4.6296296e-05 | F27: 0.0016898148 | G27: 0.0006712963 | H27: 0.9483 | I27: =VALUE(SUBSTITUTE(C27,"%",""))/100 -> 0.009828 | J27: =VALUE(SUBSTITUTE(H27,"%",""))/100 -> 0.009483 | K27: =A27-B27 -> 1 | L27: =D27/A27 -> 0.017241379 | M27: =B27/A27 -> 0.98275862
A28: 160 | B28: 153 | C28: 0.9563 | D28: 7 | E28: 0.00011574074 | F28: 0.0016550926 | G28: 0.0019097222 | H28: 0.8491 | I28: =VALUE(SUBSTITUTE(C28,"%",""))/100 -> 0.009563 | J28: =VALUE(SUBSTITUTE(H28,"%",""))/100 -> 0.008491 | K28: =A28-B28 -> 7 | L28: =D28/A28 -> 0.04375 | M28: =B28/A28 -> 0.95625
A29: 86 | B29: 79 | C29: 0.9186 | D29: 7 | E29: 0.00037037037 | F29: 0.0018865741 | G29: 0.0032407407 | H29: 0.6163 | I29: =VALUE(SUBSTITUTE(C29,"%",""))/100 -> 0.009186 | J29: =VALUE(SUBSTITUTE(H29,"%",""))/100 -> 0.006163 | K29: =A29-B29 -> 7 | L29: =D29/A29 -> 0.081395349 | M29: =B29/A29 -> 0.91860465
A30: 180 | B30: 170 | C30: 0.9444 | D30: 10 | E30: 0.0002662037 | F30: 0.0017476852 | G30: 0.0039930556 | H30: 0.7753 | I30: =VALUE(SUBSTITUTE(C30,"%",""))/100 -> 0.009444 | J30: =VALUE(SUBSTITUTE(H30,"%",""))/100 -> 0.007753 | K30: =A30-B30 -> 10 | L30: =D30/A30 -> 0.055555556 | M30: =B30/A30 -> 0.94444444
A31: 210 | B31: 192 | C31: 0.9143 | D31: 18 | E31: 0.00030092593 | F31: 0.0015740741 | G31: 0.0038773148 | H31: 0.6746 | I31: =VALUE(SUBSTITUTE(C31,"%",""))/100 -> 0.009143 | J31: =VALUE(SUBSTITUTE(H31,"%",""))/100 -> 0.006746 | K31: =A31-B31 -> 18 | L31: =D31/A31 -> 0.085714286 | M31: =B31/A31 -> 0.91428571
... A1252: 12 | B1252: 11 | C1252: 0.9167 | D1252: 1 | E1252: 3.4722222e-05 | F1252: 0.0015277778 | G1252: 0.0006712963 | H1252: 0.9167 | I1252: =VALUE(SUBSTITUTE(C1252,"%",""))/100 -> 0.009167 | J1252: =VALUE(SUBSTITUTE(H1252,"%",""))/100 -> 0.009167 | K1252: =A1252-B1252 -> 1 | L1252: =D1252/A1252 -> 0.083333333 | M1252: =B1252/A1252 -> 0.91666667

Sheet Summary
B2: Pivot Table 1: Sum of Calls
B3: Sum of Incoming Calls | C3: Sum of Answered Calls | D3: Sum of Abandoned Calls | G3: KPI SUMMARY
B4: 248373 | C4: 221234 | D4: 27139 | G4: Total Incoming Calls | H4: =SUM(Worksheet!A:A) -> 248373
G5: Total Answered Calls | H5: =SUM(Worksheet!B:B) -> 221234
B6: Pivot Table 2: Average of Answer Rate, Service Level & Waiting Time | G6: Total Abandoned Calls | H6: =SUM(Worksheet!D:D) -> 27139
B7: Average of Answer Rate | C7: Average of Service Level | D7: Average of Waiting Time | G7: Avg Answer Rate | H7: =AVERAGE(Worksheet!C:C) -> 0.92692518
B8: 0.92692518 | C8: 0.7087291 | D8: 0.0026888304 | G8: Avg Waiting Time | H8: =AVERAGE(Worksheet!G:G) -> 0.0026888304
G9: Avg Service Level | H9: =AVERAGE(Worksheet!H:H) -> 0.7087291
G26: KPI SUMMARY
G27: Answer Rate Numeric | H27: 0.0092692518
G28: Service Level Numeric | H28: 0.007087291
G29: Calls Not Answered | H29: 27139
G30: Abandonment Rate | H30: 0.073076569
G31: Answer Efficiency | H31: 0.92692343
G48: KPI SUMMARY
G49: Answer Speed | H49: 0.00028816761
G50: Talk Duration | H50: 0.0018235134
G51: Waiting Time | H51: 0.0026888304

Sheet Dashboard
A1: CALL CENTER PERFORMANCE DASHBOARD
A4: Incoming Calls | C4: Answered Calls | E4: Abandoned Calls | G4: Answer Rate | I4: Waiting Time | K4: Service Level
A6: =[1]Worksheet!P2 -> 248373 | C6: =[1]Worksheet!P3 -> 221234 | E6: =[1]Worksheet!P4 -> 27139 | G6: =[1]Worksheet!P5 -> 0.92692518 | I6: =[1]Worksheet!P6 -> 0.0026888304 | K6: =[1]Worksheet!P7 -> 0.7087291
A9: Answered vs Abandoned | G9: Performance Metrics
A27: Average Time Metrics
A45: Key Insights
A47: KEY INSIGHTS • Most incoming calls were successfully answered. • Service level remained strong. • Waiting times were manageable. • Abandoned calls represented a small percentage of total calls. • Overall call center performance was stable.
